<?xml version="1.0" encoding="UTF-8"?>
<robot xmlns:xacro="http://wiki.ros.org/xacro">

  <xacro:include filename="$(find controlko_description)/urdf/common.xacro" />

  <xacro:macro name="rrbot" params="prefix parent *origin">
    <!-- LINKS -->
    <!-- base link -->
    <link name="${prefix}base_link">
      <!-- Default inertial for Gazebo - copy and edit block from 'common.xacro'
           to get more realistic behaviour-->
      <xacro:default_inertial/>
      <visual>
        <origin xyz="0 0 0.15" rpy="0 0 0" />
        <geometry>
          <box size="0.3 0.3 0.3"/>
        </geometry>
        <material name="StoglRobotics/Violet"/>
      </visual>
      <collision>
        <origin xyz="0 0 0.15" rpy="0 0 0" />
        <geometry>
          <box size="0.3 0.3 0.3"/>
        </geometry>
      </collision>
    </link>
    <gazebo reference="${prefix}base_link">
      <material>Gazebo/Orange</material>
    </gazebo>

    <!-- link 1 -->
    <link name="${prefix}link1">
      <!-- Default inertial for Gazebo - copy and edit block from 'common.xacro'
           to get more realistic behaviour-->
      <xacro:default_inertial/>
      <visual>
        <origin xyz="0 0 0.25" rpy="0 0 0" />
        <geometry>
          <cylinder length="0.5" radius="${0.2/2}" />
        </geometry>
        <material name="StoglRobotics/DarkGrey"/>
      </visual>
      <collision>
        <origin xyz="0 0 0.25" rpy="0 0 0" />
        <geometry>
          <cylinder length="0.5" radius="${0.2/2}" />
        </geometry>
      </collision>
    </link>
    <gazebo reference="${prefix}link1">
        <material>Gazebo/Black</material>
    </gazebo>
    
    <!-- link 2 -->
    <link name="${prefix}link2">
      <!-- Default inertial for Gazebo - copy and edit block from 'common.xacro'
           to get more realistic behaviour-->
      <xacro:default_inertial/>
      <visual>
        <origin xyz="0 0 0.3" rpy="0 0 0" />
        <geometry>
          <box size="0.1 0.1 0.6"/>
        </geometry>
        <material name="StoglRobotics/LightGrey"/>
      </visual>
      <collision>
        <origin xyz="0 0 0.3" rpy="0 0 0" />
        <geometry>
          <box size="0.1 0.1 0.6"/>
        </geometry>
      </collision>
    </link>
    <gazebo reference="${prefix}link2">
      <material>Gazebo/Gray</material>
    </gazebo>

    <!-- All-zero tool frame. This frame should correspond to the TOOL frame of the robot's controller.) -->
    <link name="${prefix}tool0" />
    <!-- tool link -->

<!-- START Delete if not needed -->
    <!-- Standard frames for industrial robots. Also useful for manipulators.
         (ROS-I specs - https://wiki.ros.org/Industrial/Tutorials/WorkingWithRosIndustrialRobotSupportPackages#Standardised_links_.2F_frames)-->
    <!-- This frame should correspond to the BASE coordinate system of robot's controller.) -->
    <link name="${prefix}base" />
    <!-- Frame for mounting EEF models to a manipulator. x+ axis points forward (REP 103). -->
    <link name="${prefix}flange" />
<!-- END Delete if not needed  -->
    <!-- END LINKS -->

    <!-- JOINTS -->
    <!-- base_joint fixes base_link to the environment -->
    <joint name="${prefix}base_joint" type="fixed">
      <xacro:insert_block name="origin" />
      <parent link="${parent}" />
      <child link="${prefix}base_link" />
    </joint>
    <!-- joint 1 -->
    <joint name="${prefix}joint1" type="revolute">
      <origin xyz="0 0 0.3" rpy="0 0 0" />
      <parent link="${prefix}base_link" />
      <child link="${prefix}link1" />
      <axis xyz="0 0 1" />
      <limit effort="1000" lower="${radians(-380)}" upper="${radians(380)}" velocity="${radians(180)}" />
    </joint>
    <!-- joint 2 -->
    <joint name="${prefix}joint2" type="revolute">
      <origin xyz="0 0 0.5" rpy="0 -${pi/2} 0" />
      <parent link="${prefix}link1" />
      <child link="${prefix}link2" />
      <axis xyz="0 1 0" />
      <limit effort="1000" lower="${radians(-60)}" upper="${radians(240)}" velocity="${radians(180)}" />
    </joint>

    <!-- tool frame - fixed frame -->
    <joint name="${prefix}link2-tool0" type="fixed">
      <parent link="${prefix}link2" />
      <child link="${prefix}tool0" />
      <origin xyz="0 0 0.6" rpy="0 ${-pi} ${-pi/2}" />
    </joint>
    <!-- END JOINTS -->

<!-- START Delete if not needed -->
    <!-- Standard frames for industrial robots. Also useful for manipulators.
         (ROS-I specs - https://wiki.ros.org/Industrial/Tutorials/WorkingWithRosIndustrialRobotSupportPackages#Standardised_links_.2F_frames)-->
    <joint name="${prefix}base_link-base_joint" type="fixed">
      <origin xyz="0 0 0" rpy="0 0 0" />
      <parent link="${prefix}base_link" />
      <child link="${prefix}base" />
    </joint>

    <joint name="${prefix}tool0-flange_joint" type="fixed">
      <origin xyz="0 0 0" rpy="0 0 0" />
      <parent link="${prefix}tool0" />
      <child link="${prefix}flange" />
    </joint>
<!-- END Delete if not needed  -->


  </xacro:macro>
</robot>
